2021-09-20 at 14:26:10 | INFO | apollo_helpers.py::inner1
2021-09-20 at 14:26:10 | INFO | POST /login - Positive Test
2021-09-20 at 14:26:13 | WARNING | FAILED: Test "apollo_helpers.py::inner1" Failed with: 'dict' object is not callable
